Workbook

Sheet Read_Me
A1: Research Data and Analysis Package
A3: Paper | B3: Residential Construction Growth in Kyrgyzstan: Regional Patterns and Geographic Concentration, 2021 to 2025
A4: Primary source | B4: https://stat.gov.kg/en/opendata/category/103/
A5: Machine readable endpoint | B5: https://stat.gov.kg/en/opendata/category/103/json
A6: Official unit | B6: Thousands of square meters
A7: Primary measure | B7: Commissioned residential floor area
A8: Coverage | B8: Nine reported territories, 2021 to 2025
A9: Primary observations | B9: 45
A10: Raw preservation | B10: Construction_Raw reproduces the official source observations without derived edits.
A11: Boundary caution | B11: Administrative territorial reform in 2024 changed city and regional boundaries, especially Bishkek and Osh. Regional comparisons spanning the reform require caution.
A12: Population analysis | B12: Included as exploratory only because the same boundary reform affects denominator comparability.
A13: Workbook logic | B13: Derived measures use formulas wherever practical so calculations remain auditable.
A14: Version 2 additions | B14: Sheets Sensitivity_City_Region, HHI_Comparison, Robustness_TwoYearAvg, Decomposition_Contribution, Population_A1 were added; produced by reproduce_analysis_v2.py (reads the preserved JSON).

Sheet Construction_Raw
A1: source_region | B1: year | C1: residential_thousand_sqm | D1: unit | E1: source_url
A2: Batken oblast | B2: 2021 | C2: 63.4 | D2: thous. sq.m. | E2: https://stat.gov.kg/en/opendata/category/103/json
A3: Batken oblast | B3: 2022 | C3: 76.5 | D3: thous. sq.m. | E3: https://stat.gov.kg/en/opendata/category/103/json
A4: Batken oblast | B4: 2023 | C4: 117.3 | D4: thous. sq.m. | E4: https://stat.gov.kg/en/opendata/category/103/json
A5: Batken oblast | B5: 2024 | C5: 68.9 | D5: thous. sq.m. | E5: https://stat.gov.kg/en/opendata/category/103/json
A6: Batken oblast | B6: 2025 | C6: 71.2 | D6: thous. sq.m. | E6: https://stat.gov.kg/en/opendata/category/103/json
A7: Jalal-Abat oblast | B7: 2021 | C7: 186.1 | D7: thous. sq.m. | E7: https://stat.gov.kg/en/opendata/category/103/json
A8: Jalal-Abat oblast | B8: 2022 | C8: 211.3 | D8: thous. sq.m. | E8: https://stat.gov.kg/en/opendata/category/103/json
A9: Jalal-Abat oblast | B9: 2023 | C9: 267.7 | D9: thous. sq.m. | E9: https://stat.gov.kg/en/opendata/category/103/json
A10: Jalal-Abat oblast | B10: 2024 | C10: 299.9 | D10: thous. sq.m. | E10: https://stat.gov.kg/en/opendata/category/103/json
A11: Jalal-Abat oblast | B11: 2025 | C11: 311.8 | D11: thous. sq.m. | E11: https://stat.gov.kg/en/opendata/category/103/json
A12: Yssyk-Kul oblast | B12: 2021 | C12: 85.8 | D12: thous. sq.m. | E12: https://stat.gov.kg/en/opendata/category/103/json
A13: Yssyk-Kul oblast | B13: 2022 | C13: 89.2 | D13: thous. sq.m. | E13: https://stat.gov.kg/en/opendata/category/103/json
... A46: Osh city | B46: 2025 | C46: 194.4 | D46: thous. sq.m. | E46: https://stat.gov.kg/en/opendata/category/103/json

Sheet Cleaning_Log
A1: step | B1: operation | C1: rationale | D1: effect_on_values
A2: 1 | B2: Preserved official observations in Construction_Raw | C2: Maintain an untouched analytical audit trail | D2: None
A3: 2 | B3: Standardized English territory names | C3: Use consistent manuscript terminology | D3: Names only
A4: 3 | B4: Converted thousands of square meters to square meters | C4: Create residential_sqm using multiplication by 1000 | D4: Unit conversion only
A5: 4 | B5: Reshaped data to long format | C5: One territory year observation per row | D5: None
A6: 5 | B6: Calculated totals, growth, CAGR, shares, index, and HHI | C6: Answer RQ1 to RQ4 reproducibly | D6: Derived variables only
A7: 6 | B7: Added 2021 to 2025 population as exploratory data | C7: Optional intensity analysis | D7: No change to construction values
A8: 7 | B8: Flagged 2024 administrative territorial reform | C8: Avoid silent comparison of changing territorial boundaries | D8: Interpretive limitation only
A9: 8 | B9: Verified all 45 clean values against preserved JSON extract (max difference 0.0) | C9: Independent audit of transcription | D9: None
A10: 9 | B10: Added city+region sensitivity, normalized HHI, two-year averages, contribution decomposition | C10: Address 2024 boundary reform and endpoint sensitivity | D10: Derived variables only

Sheet Construction_Clean
A1: year | B1: region | C1: residential_thousand_sqm | D1: residential_sqm | E1: national_total_sqm | F1: regional_share_pct | G1: annual_growth_pct | H1: regional_growth_2021_2025_pct | I1: cagr_2021_2025_pct | J1: regional_share_change_pp | K1: index_2021 | L1: hhi
A2: 2021 | B2: Batken Region | C2: 63.4 | D2: =C2*1000 | E2: =SUM($D$2:$D$10) | F2: =D2/E2*100 | H2: =(C$38/C$2-1)*100 | I2: =((C$38/C$2)^(1/4)-1)*100 | J2: =F$38-F$2 | K2: =C2/C$2*100 | L2: =(F2/100)^2+(F3/100)^2+(F4/100)^2+(F5/100)^2+(F6/100)^2+(F7/100)^2+(F8/100)^2+(F9/100)^2+(F10/100)^2
A3: 2021 | B3: Jalal Abad Region | C3: 186.1 | D3: =C3*1000 | E3: =SUM($D$2:$D$10) | F3: =D3/E3*100 | H3: =(C$39/C$3-1)*100 | I3: =((C$39/C$3)^(1/4)-1)*100 | J3: =F$39-F$3 | K3: =C3/C$3*100 | L3: =(F2/100)^2+(F3/100)^2+(F4/100)^2+(F5/100)^2+(F6/100)^2+(F7/100)^2+(F8/100)^2+(F9/100)^2+(F10/100)^2
A4: 2021 | B4: Issyk Kul Region | C4: 85.8 | D4: =C4*1000 | E4: =SUM($D$2:$D$10) | F4: =D4/E4*100 | H4: =(C$40/C$4-1)*100 | I4: =((C$40/C$4)^(1/4)-1)*100 | J4: =F$40-F$4 | K4: =C4/C$4*100 | L4: =(F2/100)^2+(F3/100)^2+(F4/100)^2+(F5/100)^2+(F6/100)^2+(F7/100)^2+(F8/100)^2+(F9/100)^2+(F10/100)^2
A5: 2021 | B5: Naryn Region | C5: 43.1 | D5: =C5*1000 | E5: =SUM($D$2:$D$10) | F5: =D5/E5*100 | H5: =(C$41/C$5-1)*100 | I5: =((C$41/C$5)^(1/4)-1)*100 | J5: =F$41-F$5 | K5: =C5/C$5*100 | L5: =(F2/100)^2+(F3/100)^2+(F4/100)^2+(F5/100)^2+(F6/100)^2+(F7/100)^2+(F8/100)^2+(F9/100)^2+(F10/100)^2
A6: 2021 | B6: Osh Region | C6: 237.9 | D6: =C6*1000 | E6: =SUM($D$2:$D$10) | F6: =D6/E6*100 | H6: =(C$42/C$6-1)*100 | I6: =((C$42/C$6)^(1/4)-1)*100 | J6: =F$42-F$6 | K6: =C6/C$6*100 | L6: =(F2/100)^2+(F3/100)^2+(F4/100)^2+(F5/100)^2+(F6/100)^2+(F7/100)^2+(F8/100)^2+(F9/100)^2+(F10/100)^2
A7: 2021 | B7: Talas Region | C7: 63.2 | D7: =C7*1000 | E7: =SUM($D$2:$D$10) | F7: =D7/E7*100 | H7: =(C$43/C$7-1)*100 | I7: =((C$43/C$7)^(1/4)-1)*100 | J7: =F$43-F$7 | K7: =C7/C$7*100 | L7: =(F2/100)^2+(F3/100)^2+(F4/100)^2+(F5/100)^2+(F6/100)^2+(F7/100)^2+(F8/100)^2+(F9/100)^2+(F10/100)^2
A8: 2021 | B8: Chui Region | C8: 168.3 | D8: =C8*1000 | E8: =SUM($D$2:$D$10) | F8: =D8/E8*100 | H8: =(C$44/C$8-1)*100 | I8: =((C$44/C$8)^(1/4)-1)*100 | J8: =F$44-F$8 | K8: =C8/C$8*100 | L8: =(F2/100)^2+(F3/100)^2+(F4/100)^2+(F5/100)^2+(F6/100)^2+(F7/100)^2+(F8/100)^2+(F9/100)^2+(F10/100)^2
A9: 2021 | B9: Bishkek City | C9: 348.6 | D9: =C9*1000 | E9: =SUM($D$2:$D$10) | F9: =D9/E9*100 | H9: =(C$45/C$9-1)*100 | I9: =((C$45/C$9)^(1/4)-1)*100 | J9: =F$45-F$9 | K9: =C9/C$9*100 | L9: =(F2/100)^2+(F3/100)^2+(F4/100)^2+(F5/100)^2+(F6/100)^2+(F7/100)^2+(F8/100)^2+(F9/100)^2+(F10/100)^2
A10: 2021 | B10: Osh City | C10: 116.8 | D10: =C10*1000 | E10: =SUM($D$2:$D$10) | F10: =D10/E10*100 | H10: =(C$46/C$10-1)*100 | I10: =((C$46/C$10)^(1/4)-1)*100 | J10: =F$46-F$10 | K10: =C10/C$10*100 | L10: =(F2/100)^2+(F3/100)^2+(F4/100)^2+(F5/100)^2+(F6/100)^2+(F7/100)^2+(F8/100)^2+(F9/100)^2+(F10/100)^2
A11: 2022 | B11: Batken Region | C11: 76.5 | D11: =C11*1000 | E11: =SUM($D$11:$D$19) | F11: =D11/E11*100 | G11: =(C11/C2-1)*100 | H11: =(C$38/C$2-1)*100 | I11: =((C$38/C$2)^(1/4)-1)*100 | J11: =F$38-F$2 | K11: =C11/C$2*100 | L11: =(F11/100)^2+(F12/100)^2+(F13/100)^2+(F14/100)^2+(F15/100)^2+(F16/100)^2+(F17/100)^2+(F18/100)^2+(F19/100)^2
A12: 2022 | B12: Jalal Abad Region | C12: 211.3 | D12: =C12*1000 | E12: =SUM($D$11:$D$19) | F12: =D12/E12*100 | G12: =(C12/C3-1)*100 | H12: =(C$39/C$3-1)*100 | I12: =((C$39/C$3)^(1/4)-1)*100 | J12: =F$39-F$3 | K12: =C12/C$3*100 | L12: =(F11/100)^2+(F12/100)^2+(F13/100)^2+(F14/100)^2+(F15/100)^2+(F16/100)^2+(F17/100)^2+(F18/100)^2+(F19/100)^2
A13: 2022 | B13: Issyk Kul Region | C13: 89.2 | D13: =C13*1000 | E13: =SUM($D$11:$D$19) | F13: =D13/E13*100 | G13: =(C13/C4-1)*100 | H13: =(C$40/C$4-1)*100 | I13: =((C$40/C$4)^(1/4)-1)*100 | J13: =F$40-F$4 | K13: =C13/C$4*100 | L13: =(F11/100)^2+(F12/100)^2+(F13/100)^2+(F14/100)^2+(F15/100)^2+(F16/100)^2+(F17/100)^2+(F18/100)^2+(F19/100)^2
A14: 2022 | B14: Naryn Region | C14: 40.1 | D14: =C14*1000 | E14: =SUM($D$11:$D$19) | F14: =D14/E14*100 | G14: =(C14/C5-1)*100 | H14: =(C$41/C$5-1)*100 | I14: =((C$41/C$5)^(1/4)-1)*100 | J14: =F$41-F$5 | K14: =C14/C$5*100 | L14: =(F11/100)^2+(F12/100)^2+(F13/100)^2+(F14/100)^2+(F15/100)^2+(F16/100)^2+(F17/100)^2+(F18/100)^2+(F19/100)^2
A15: 2022 | B15: Osh Region | C15: 276.7 | D15: =C15*1000 | E15: =SUM($D$11:$D$19) | F15: =D15/E15*100 | G15: =(C15/C6-1)*100 | H15: =(C$42/C$6-1)*100 | I15: =((C$42/C$6)^(1/4)-1)*100 | J15: =F$42-F$6 | K15: =C15/C$6*100 | L15: =(F11/100)^2+(F12/100)^2+(F13/100)^2+(F14/100)^2+(F15/100)^2+(F16/100)^2+(F17/100)^2+(F18/100)^2+(F19/100)^2
A16: 2022 | B16: Talas Region | C16: 69 | D16: =C16*1000 | E16: =SUM($D$11:$D$19) | F16: =D16/E16*100 | G16: =(C16/C7-1)*100 | H16: =(C$43/C$7-1)*100 | I16: =((C$43/C$7)^(1/4)-1)*100 | J16: =F$43-F$7 | K16: =C16/C$7*100 | L16: =(F11/100)^2+(F12/100)^2+(F13/100)^2+(F14/100)^2+(F15/100)^2+(F16/100)^2+(F17/100)^2+(F18/100)^2+(F19/100)^2
A17: 2022 | B17: Chui Region | C17: 221.3 | D17: =C17*1000 | E17: =SUM($D$11:$D$19) | F17: =D17/E17*100 | G17: =(C17/C8-1)*100 | H17: =(C$44/C$8-1)*100 | I17: =((C$44/C$8)^(1/4)-1)*100 | J17: =F$44-F$8 | K17: =C17/C$8*100 | L17: =(F11/100)^2+(F12/100)^2+(F13/100)^2+(F14/100)^2+(F15/100)^2+(F16/100)^2+(F17/100)^2+(F18/100)^2+(F19/100)^2
A18: 2022 | B18: Bishkek City | C18: 379.9 | D18: =C18*1000 | E18: =SUM($D$11:$D$19) | F18: =D18/E18*100 | G18: =(C18/C9-1)*100 | H18: =(C$45/C$9-1)*100 | I18: =((C$45/C$9)^(1/4)-1)*100 | J18: =F$45-F$9 | K18: =C18/C$9*100 | L18: =(F11/100)^2+(F12/100)^2+(F13/100)^2+(F14/100)^2+(F15/100)^2+(F16/100)^2+(F17/100)^2+(F18/100)^2+(F19/100)^2
A19: 2022 | B19: Osh City | C19: 98.6 | D19: =C19*1000 | E19: =SUM($D$11:$D$19) | F19: =D19/E19*100 | G19: =(C19/C10-1)*100 | H19: =(C$46/C$10-1)*100 | I19: =((C$46/C$10)^(1/4)-1)*100 | J19: =F$46-F$10 | K19: =C19/C$10*100 | L19: =(F11/100)^2+(F12/100)^2+(F13/100)^2+(F14/100)^2+(F15/100)^2+(F16/100)^2+(F17/100)^2+(F18/100)^2+(F19/100)^2
A20: 2023 | B20: Batken Region | C20: 117.3 | D20: =C20*1000 | E20: =SUM($D$20:$D$28) | F20: =D20/E20*100 | G20: =(C20/C11-1)*100 | H20: =(C$38/C$2-1)*100 | I20: =((C$38/C$2)^(1/4)-1)*100 | J20: =F$38-F$2 | K20: =C20/C$2*100 | L20: =(F20/100)^2+(F21/100)^2+(F22/100)^2+(F23/100)^2+(F24/100)^2+(F25/100)^2+(F26/100)^2+(F27/100)^2+(F28/100)^2
A21: 2023 | B21: Jalal Abad Region | C21: 267.7 | D21: =C21*1000 | E21: =SUM($D$20:$D$28) | F21: =D21/E21*100 | G21: =(C21/C12-1)*100 | H21: =(C$39/C$3-1)*100 | I21: =((C$39/C$3)^(1/4)-1)*100 | J21: =F$39-F$3 | K21: =C21/C$3*100 | L21: =(F20/100)^2+(F21/100)^2+(F22/100)^2+(F23/100)^2+(F24/100)^2+(F25/100)^2+(F26/100)^2+(F27/100)^2+(F28/100)^2
A22: 2023 | B22: Issyk Kul Region | C22: 63.9 | D22: =C22*1000 | E22: =SUM($D$20:$D$28) | F22: =D22/E22*100 | G22: =(C22/C13-1)*100 | H22: =(C$40/C$4-1)*100 | I22: =((C$40/C$4)^(1/4)-1)*100 | J22: =F$40-F$4 | K22: =C22/C$4*100 | L22: =(F20/100)^2+(F21/100)^2+(F22/100)^2+(F23/100)^2+(F24/100)^2+(F25/100)^2+(F26/100)^2+(F27/100)^2+(F28/100)^2
A23: 2023 | B23: Naryn Region | C23: 29.4 | D23: =C23*1000 | E23: =SUM($D$20:$D$28) | F23: =D23/E23*100 | G23: =(C23/C14-1)*100 | H23: =(C$41/C$5-1)*100 | I23: =((C$41/C$5)^(1/4)-1)*100 | J23: =F$41-F$5 | K23: =C23/C$5*100 | L23: =(F20/100)^2+(F21/100)^2+(F22/100)^2+(F23/100)^2+(F24/100)^2+(F25/100)^2+(F26/100)^2+(F27/100)^2+(F28/100)^2
A24: 2023 | B24: Osh Region | C24: 240.6 | D24: =C24*1000 | E24: =SUM($D$20:$D$28) | F24: =D24/E24*100 | G24: =(C24/C15-1)*100 | H24: =(C$42/C$6-1)*100 | I24: =((C$42/C$6)^(1/4)-1)*100 | J24: =F$42-F$6 | K24: =C24/C$6*100 | L24: =(F20/100)^2+(F21/100)^2+(F22/100)^2+(F23/100)^2+(F24/100)^2+(F25/100)^2+(F26/100)^2+(F27/100)^2+(F28/100)^2
A25: 2023 | B25: Talas Region | C25: 60.1 | D25: =C25*1000 | E25: =SUM($D$20:$D$28) | F25: =D25/E25*100 | G25: =(C25/C16-1)*100 | H25: =(C$43/C$7-1)*100 | I25: =((C$43/C$7)^(1/4)-1)*100 | J25: =F$43-F$7 | K25: =C25/C$7*100 | L25: =(F20/100)^2+(F21/100)^2+(F22/100)^2+(F23/100)^2+(F24/100)^2+(F25/100)^2+(F26/100)^2+(F27/100)^2+(F28/100)^2
A26: 2023 | B26: Chui Region | C26: 218.2 | D26: =C26*1000 | E26: =SUM($D$20:$D$28) | F26: =D26/E26*100 | G26: =(C26/C17-1)*100 | H26: =(C$44/C$8-1)*100 | I26: =((C$44/C$8)^(1/4)-1)*100 | J26: =F$44-F$8 | K26: =C26/C$8*100 | L26: =(F20/100)^2+(F21/100)^2+(F22/100)^2+(F23/100)^2+(F24/100)^2+(F25/100)^2+(F26/100)^2+(F27/100)^2+(F28/100)^2
A27: 2023 | B27: Bishkek City | C27: 513.7 | D27: =C27*1000 | E27: =SUM($D$20:$D$28) | F27: =D27/E27*100 | G27: =(C27/C18-1)*100 | H27: =(C$45/C$9-1)*100 | I27: =((C$45/C$9)^(1/4)-1)*100 | J27: =F$45-F$9 | K27: =C27/C$9*100 | L27: =(F20/100)^2+(F21/100)^2+(F22/100)^2+(F23/100)^2+(F24/100)^2+(F25/100)^2+(F26/100)^2+(F27/100)^2+(F28/100)^2
A28: 2023 | B28: Osh City | C28: 88 | D28: =C28*1000 | E28: =SUM($D$20:$D$28) | F28: =D28/E28*100 | G28: =(C28/C19-1)*100 | H28: =(C$46/C$10-1)*100 | I28: =((C$46/C$10)^(1/4)-1)*100 | J28: =F$46-F$10 | K28: =C28/C$10*100 | L28: =(F20/100)^2+(F21/100)^2+(F22/100)^2+(F23/100)^2+(F24/100)^2+(F25/100)^2+(F26/100)^2+(F27/100)^2+(F28/100)^2
A29: 2024 | B29: Batken Region | C29: 68.9 | D29: =C29*1000 | E29: =SUM($D$29:$D$37) | F29: =D29/E29*100 | G29: =(C29/C20-1)*100 | H29: =(C$38/C$2-1)*100 | I29: =((C$38/C$2)^(1/4)-1)*100 | J29: =F$38-F$2 | K29: =C29/C$2*100 | L29: =(F29/100)^2+(F30/100)^2+(F31/100)^2+(F32/100)^2+(F33/100)^2+(F34/100)^2+(F35/100)^2+(F36/100)^2+(F37/100)^2
A30: 2024 | B30: Jalal Abad Region | C30: 299.9 | D30: =C30*1000 | E30: =SUM($D$29:$D$37) | F30: =D30/E30*100 | G30: =(C30/C21-1)*100 | H30: =(C$39/C$3-1)*100 | I30: =((C$39/C$3)^(1/4)-1)*100 | J30: =F$39-F$3 | K30: =C30/C$3*100 | L30: =(F29/100)^2+(F30/100)^2+(F31/100)^2+(F32/100)^2+(F33/100)^2+(F34/100)^2+(F35/100)^2+(F36/100)^2+(F37/100)^2
A31: 2024 | B31: Issyk Kul Region | C31: 82.9 | D31: =C31*1000 | E31: =SUM($D$29:$D$37) | F31: =D31/E31*100 | G31: =(C31/C22-1)*100 | H31: =(C$40/C$4-1)*100 | I31: =((C$40/C$4)^(1/4)-1)*100 | J31: =F$40-F$4 | K31: =C31/C$4*100 | L31: =(F29/100)^2+(F30/100)^2+(F31/100)^2+(F32/100)^2+(F33/100)^2+(F34/100)^2+(F35/100)^2+(F36/100)^2+(F37/100)^2
A32: 2024 | B32: Naryn Region | C32: 32 | D32: =C32*1000 | E32: =SUM($D$29:$D$37) | F32: =D32/E32*100 | G32: =(C32/C23-1)*100 | H32: =(C$41/C$5-1)*100 | I32: =((C$41/C$5)^(1/4)-1)*100 | J32: =F$41-F$5 | K32: =C32/C$5*100 | L32: =(F29/100)^2+(F30/100)^2+(F31/100)^2+(F32/100)^2+(F33/100)^2+(F34/100)^2+(F35/100)^2+(F36/100)^2+(F37/100)^2
A33: 2024 | B33: Osh Region | C33: 190.8 | D33: =C33*1000 | E33: =SUM($D$29:$D$37) | F33: =D33/E33*100 | G33: =(C33/C24-1)*100 | H33: =(C$42/C$6-1)*100 | I33: =((C$42/C$6)^(1/4)-1)*100 | J33: =F$42-F$6 | K33: =C33/C$6*100 | L33: =(F29/100)^2+(F30/100)^2+(F31/100)^2+(F32/100)^2+(F33/100)^2+(F34/100)^2+(F35/100)^2+(F36/100)^2+(F37/100)^2
A34: 2024 | B34: Talas Region | C34: 83.7 | D34: =C34*1000 | E34: =SUM($D$29:$D$37) | F34: =D34/E34*100 | G34: =(C34/C25-1)*100 | H34: =(C$43/C$7-1)*100 | I34: =((C$43/C$7)^(1/4)-1)*100 | J34: =F$43-F$7 | K34: =C34/C$7*100 | L34: =(F29/100)^2+(F30/100)^2+(F31/100)^2+(F32/100)^2+(F33/100)^2+(F34/100)^2+(F35/100)^2+(F36/100)^2+(F37/100)^2
A35: 2024 | B35: Chui Region | C35: 151.1 | D35: =C35*1000 | E35: =SUM($D$29:$D$37) | F35: =D35/E35*100 | G35: =(C35/C26-1)*100 | H35: =(C$44/C$8-1)*100 | I35: =((C$44/C$8)^(1/4)-1)*100 | J35: =F$44-F$8 | K35: =C35/C$8*100 | L35: =(F29/100)^2+(F30/100)^2+(F31/100)^2+(F32/100)^2+(F33/100)^2+(F34/100)^2+(F35/100)^2+(F36/100)^2+(F37/100)^2
A36: 2024 | B36: Bishkek City | C36: 539.1 | D36: =C36*1000 | E36: =SUM($D$29:$D$37) | F36: =D36/E36*100 | G36: =(C36/C27-1)*100 | H36: =(C$45/C$9-1)*100 | I36: =((C$45/C$9)^(1/4)-1)*100 | J36: =F$45-F$9 | K36: =C36/C$9*100 | L36: =(F29/100)^2+(F30/100)^2+(F31/100)^2+(F32/100)^2+(F33/100)^2+(F34/100)^2+(F35/100)^2+(F36/100)^2+(F37/100)^2
A37: 2024 | B37: Osh City | C37: 125 | D37: =C37*1000 | E37: =SUM($D$29:$D$37) | F37: =D37/E37*100 | G37: =(C37/C28-1)*100 | H37: =(C$46/C$10-1)*100 | I37: =((C$46/C$10)^(1/4)-1)*100 | J37: =F$46-F$10 | K37: =C37/C$10*100 | L37: =(F29/100)^2+(F30/100)^2+(F31/100)^2+(F32/100)^2+(F33/100)^2+(F34/100)^2+(F35/100)^2+(F36/100)^2+(F37/100)^2
A38: 2025 | B38: Batken Region | C38: 71.2 | D38: =C38*1000 | E38: =SUM($D$38:$D$46) | F38: =D38/E38*100 | G38: =(C38/C29-1)*100 | H38: =(C$38/C$2-1)*100 | I38: =((C$38/C$2)^(1/4)-1)*100 | J38: =F$38-F$2 | K38: =C38/C$2*100 | L38: =(F38/100)^2+(F39/100)^2+(F40/100)^2+(F41/100)^2+(F42/100)^2+(F43/100)^2+(F44/100)^2+(F45/100)^2+(F46/100)^2
A39: 2025 | B39: Jalal Abad Region | C39: 311.8 | D39: =C39*1000 | E39: =SUM($D$38:$D$46) | F39: =D39/E39*100 | G39: =(C39/C30-1)*100 | H39: =(C$39/C$3-1)*100 | I39: =((C$39/C$3)^(1/4)-1)*100 | J39: =F$39-F$3 | K39: =C39/C$3*100 | L39: =(F38/100)^2+(F39/100)^2+(F40/100)^2+(F41/100)^2+(F42/100)^2+(F43/100)^2+(F44/100)^2+(F45/100)^2+(F46/100)^2
A40: 2025 | B40: Issyk Kul Region | C40: 86.3 | D40: =C40*1000 | E40: =SUM($D$38:$D$46) | F40: =D40/E40*100 | G40: =(C40/C31-1)*100 | H40: =(C$40/C$4-1)*100 | I40: =((C$40/C$4)^(1/4)-1)*100 | J40: =F$40-F$4 | K40: =C40/C$4*100 | L40: =(F38/100)^2+(F39/100)^2+(F40/100)^2+(F41/100)^2+(F42/100)^2+(F43/100)^2+(F44/100)^2+(F45/100)^2+(F46/100)^2
...

Sheet National_Summary
A1: year | B1: national_total_thousand_sqm | C1: national_total_sqm | D1: annual_growth_pct | E1: hhi
A2: 2021 | B2: =SUM(Construction_Clean!C2:C10) | C2: =B2*1000 | E2: =(Construction_Clean!F2/100)^2+(Construction_Clean!F3/100)^2+(Construction_Clean!F4/100)^2+(Construction_Clean!F5/100)^2+(Construction_Clean!F6/100)^2+(Construction_Clean!F7/100)^2+(Construction_Clean!F8/100)^2+(Construction_Clean!F9/100)^2+(Construction_Clean!F10/100)^2
A3: 2022 | B3: =SUM(Construction_Clean!C11:C19) | C3: =B3*1000 | D3: =(B3/B2-1)*100 | E3: =(Construction_Clean!F11/100)^2+(Construction_Clean!F12/100)^2+(Construction_Clean!F13/100)^2+(Construction_Clean!F14/100)^2+(Construction_Clean!F15/100)^2+(Construction_Clean!F16/100)^2+(Construction_Clean!F17/100)^2+(Construction_Clean!F18/100)^2+(Construction_Clean!F19/100)^2
A4: 2023 | B4: =SUM(Construction_Clean!C20:C28) | C4: =B4*1000 | D4: =(B4/B3-1)*100 | E4: =(Construction_Clean!F20/100)^2+(Construction_Clean!F21/100)^2+(Construction_Clean!F22/100)^2+(Construction_Clean!F23/100)^2+(Construction_Clean!F24/100)^2+(Construction_Clean!F25/100)^2+(Construction_Clean!F26/100)^2+(Construction_Clean!F27/100)^2+(Construction_Clean!F28/100)^2
A5: 2024 | B5: =SUM(Construction_Clean!C29:C37) | C5: =B5*1000 | D5: =(B5/B4-1)*100 | E5: =(Construction_Clean!F29/100)^2+(Construction_Clean!F30/100)^2+(Construction_Clean!F31/100)^2+(Construction_Clean!F32/100)^2+(Construction_Clean!F33/100)^2+(Construction_Clean!F34/100)^2+(Construction_Clean!F35/100)^2+(Construction_Clean!F36/100)^2+(Construction_Clean!F37/100)^2
A6: 2025 | B6: =SUM(Construction_Clean!C38:C46) | C6: =B6*1000 | D6: =(B6/B5-1)*100 | E6: =(Construction_Clean!F38/100)^2+(Construction_Clean!F39/100)^2+(Construction_Clean!F40/100)^2+(Construction_Clean!F41/100)^2+(Construction_Clean!F42/100)^2+(Construction_Clean!F43/100)^2+(Construction_Clean!F44/100)^2+(Construction_Clean!F45/100)^2+(Construction_Clean!F46/100)^2
A8: Metric | B8: Value
A9: Overall growth, 2021 to 2025, percent | B9: =(B6/B2-1)*100
A10: National CAGR, 2021 to 2025, percent | B10: =((B6/B2)^(1/4)-1)*100
A11: HHI change, 2021 to 2025 | B11: =E6-E2

Sheet Regional_Summary
A1: region | B1: 2021_thousand_sqm | C1: 2025_thousand_sqm | D1: absolute_change_thousand_sqm | E1: pct_change | F1: cagr_pct | G1: share_2021_pct | H1: share_2025_pct | I1: share_change_pp
A2: Batken Region | B2: =Construction_Clean!C2 | C2: =Construction_Clean!C38 | D2: =C2-B2 | E2: =(C2/B2-1)*100 | F2: =((C2/B2)^(1/4)-1)*100 | G2: =Construction_Clean!F2 | H2: =Construction_Clean!F38 | I2: =H2-G2
A3: Jalal Abad Region | B3: =Construction_Clean!C3 | C3: =Construction_Clean!C39 | D3: =C3-B3 | E3: =(C3/B3-1)*100 | F3: =((C3/B3)^(1/4)-1)*100 | G3: =Construction_Clean!F3 | H3: =Construction_Clean!F39 | I3: =H3-G3
A4: Issyk Kul Region | B4: =Construction_Clean!C4 | C4: =Construction_Clean!C40 | D4: =C4-B4 | E4: =(C4/B4-1)*100 | F4: =((C4/B4)^(1/4)-1)*100 | G4: =Construction_Clean!F4 | H4: =Construction_Clean!F40 | I4: =H4-G4
A5: Naryn Region | B5: =Construction_Clean!C5 | C5: =Construction_Clean!C41 | D5: =C5-B5 | E5: =(C5/B5-1)*100 | F5: =((C5/B5)^(1/4)-1)*100 | G5: =Construction_Clean!F5 | H5: =Construction_Clean!F41 | I5: =H5-G5
A6: Osh Region | B6: =Construction_Clean!C6 | C6: =Construction_Clean!C42 | D6: =C6-B6 | E6: =(C6/B6-1)*100 | F6: =((C6/B6)^(1/4)-1)*100 | G6: =Construction_Clean!F6 | H6: =Construction_Clean!F42 | I6: =H6-G6
A7: Talas Region | B7: =Construction_Clean!C7 | C7: =Construction_Clean!C43 | D7: =C7-B7 | E7: =(C7/B7-1)*100 | F7: =((C7/B7)^(1/4)-1)*100 | G7: =Construction_Clean!F7 | H7: =Construction_Clean!F43 | I7: =H7-G7
A8: Chui Region | B8: =Construction_Clean!C8 | C8: =Construction_Clean!C44 | D8: =C8-B8 | E8: =(C8/B8-1)*100 | F8: =((C8/B8)^(1/4)-1)*100 | G8: =Construction_Clean!F8 | H8: =Construction_Clean!F44 | I8: =H8-G8
A9: Bishkek City | B9: =Construction_Clean!C9 | C9: =Construction_Clean!C45 | D9: =C9-B9 | E9: =(C9/B9-1)*100 | F9: =((C9/B9)^(1/4)-1)*100 | G9: =Construction_Clean!F9 | H9: =Construction_Clean!F45 | I9: =H9-G9
A10: Osh City | B10: =Construction_Clean!C10 | C10: =Construction_Clean!C46 | D10: =C10-B10 | E10: =(C10/B10-1)*100 | F10: =((C10/B10)^(1/4)-1)*100 | G10: =Construction_Clean!F10 | H10: =Construction_Clean!F46 | I10: =H10-G10

Sheet Population_Exploratory
A1: year | B1: region | C1: population_thousand | D1: population_persons | E1: residential_sqm | F1: residential_sqm_per_1000_residents | G1: comparability_note | H1: source_url
A2: 2021 | B2: Batken Region | C2: 549 | D2: =C2*1000 | E2: =Construction_Clean!D2 | F2: =E2/D2*1000 | H2: https://www.stat.gov.kg/en/opendata/category/39/
A3: 2021 | B3: Jalal Abad Region | C3: 1266.3 | D3: =C3*1000 | E3: =Construction_Clean!D3 | F3: =E3/D3*1000 | H3: https://www.stat.gov.kg/en/opendata/category/39/
A4: 2021 | B4: Issyk Kul Region | C4: 527.7 | D4: =C4*1000 | E4: =Construction_Clean!D4 | F4: =E4/D4*1000 | H4: https://www.stat.gov.kg/en/opendata/category/39/
A5: 2021 | B5: Naryn Region | C5: 303.4 | D5: =C5*1000 | E5: =Construction_Clean!D5 | F5: =E5/D5*1000 | H5: https://www.stat.gov.kg/en/opendata/category/39/
A6: 2021 | B6: Osh Region | C6: 1410.8 | D6: =C6*1000 | E6: =Construction_Clean!D6 | F6: =E6/D6*1000 | H6: https://www.stat.gov.kg/en/opendata/category/39/
A7: 2021 | B7: Talas Region | C7: 267.6 | D7: =C7*1000 | E7: =Construction_Clean!D7 | F7: =E7/D7*1000 | H7: https://www.stat.gov.kg/en/opendata/category/39/
A8: 2021 | B8: Chui Region | C8: 1038.7 | D8: =C8*1000 | E8: =Construction_Clean!D8 | F8: =E8/D8*1000 | H8: https://www.stat.gov.kg/en/opendata/category/39/
A9: 2021 | B9: Bishkek City | C9: 1088.3 | D9: =C9*1000 | E9: =Construction_Clean!D9 | F9: =E9/D9*1000 | H9: https://www.stat.gov.kg/en/opendata/category/39/
A10: 2021 | B10: Osh City | C10: 337.8 | D10: =C10*1000 | E10: =Construction_Clean!D10 | F10: =E10/D10*1000 | H10: https://www.stat.gov.kg/en/opendata/category/39/
A11: 2022 | B11: Batken Region | C11: 559.5 | D11: =C11*1000 | E11: =Construction_Clean!D11 | F11: =E11/D11*1000 | H11: https://www.stat.gov.kg/en/opendata/category/39/
A12: 2022 | B12: Jalal Abad Region | C12: 1288.4 | D12: =C12*1000 | E12: =Construction_Clean!D12 | F12: =E12/D12*1000 | H12: https://www.stat.gov.kg/en/opendata/category/39/
A13: 2022 | B13: Issyk Kul Region | C13: 533.8 | D13: =C13*1000 | E13: =Construction_Clean!D13 | F13: =E13/D13*1000 | H13: https://www.stat.gov.kg/en/opendata/category/39/
... A32: 2024 | B32: Naryn Region | C32: 312.1 | D32: =C32*1000 | E32: =Construction_Clean!D32 | F32: =E32/D32*1000 | H32: https://www.stat.gov.kg/en/opendata/category/39/
A33: 2024 | B33: Osh Region | C33: 1393.6 | D33: =C33*1000 | E33: =Construction_Clean!D33 | F33: =E33/D33*1000 | G33: Interpret cautiously because 2024 territorial reform changed relevant boundaries. | H33: https://www.stat.gov.kg/en/opendata/category/39/
A34: 2024 | B34: Talas Region | C34: 277.1 | D34: =C34*1000 | E34: =Construction_Clean!D34 | F34: =E34/D34*1000 | H34: https://www.stat.gov.kg/en/opendata/category/39/
A35: 2024 | B35: Chui Region | C35: 957.6 | D35: =C35*1000 | E35: =Construction_Clean!D35 | F35: =E35/D35*1000 | G35: Interpret cautiously because 2024 territorial reform changed relevant boundaries. | H35: https://www.stat.gov.kg/en/opendata/category/39/
A36: 2024 | B36: Bishkek City | C36: 1294.8 | D36: =C36*1000 | E36: =Construction_Clean!D36 | F36: =E36/D36*1000 | G36: Interpret cautiously because 2024 territorial reform changed relevant boundaries. | H36: https://www.stat.gov.kg/en/opendata/category/39/
A37: 2024 | B37: Osh City | C37: 463.1 | D37: =C37*1000 | E37: =Construction_Clean!D37 | F37: =E37/D37*1000 | G37: Interpret cautiously because 2024 territorial reform changed relevant boundaries. | H37: https://www.stat.gov.kg/en/opendata/category/39/
A38: 2025 | B38: Batken Region | C38: 594.7 | D38: =C38*1000 | E38: =Construction_Clean!D38 | F38: =E38/D38*1000 | H38: https://www.stat.gov.kg/en/opendata/category/39/
A39: 2025 | B39: Jalal Abad Region | C39: 1358.5 | D39: =C39*1000 | E39: =Construction_Clean!D39 | F39: =E39/D39*1000 | H39: https://www.stat.gov.kg/en/opendata/category/39/
A40: 2025 | B40: Issyk Kul Region | C40: 549.8 | D40: =C40*1000 | E40: =Construction_Clean!D40 | F40: =E40/D40*1000 | H40: https://www.stat.gov.kg/en/opendata/category/39/
A41: 2025 | B41: Naryn Region | C41: 314.9 | D41: =C41*1000 | E41: =Construction_Clean!D41 | F41: =E41/D41*1000 | H41: https://www.stat.gov.kg/en/opendata/category/39/
A42: 2025 | B42: Osh Region | C42: 1416.7 | D42: =C42*1000 | E42: =Construction_Clean!D42 | F42: =E42/D42*1000 | G42: Interpret cautiously because 2024 territorial reform changed relevant boundaries. | H42: https://www.stat.gov.kg/en/opendata/category/39/
A43: 2025 | B43: Talas Region | C43: 280.5 | D43: =C43*1000 | E43: =Construction_Clean!D43 | F43: =E43/D43*1000 | H43: https://www.stat.gov.kg/en/opendata/category/39/
A44: 2025 | B44: Chui Region | C44: 971.3 | D44: =C44*1000 | E44: =Construction_Clean!D44 | F44: =E44/D44*1000 | G44: Interpret cautiously because 2024 territorial reform changed relevant boundaries. | H44: https://www.stat.gov.kg/en/opendata/category/39/
A45: 2025 | B45: Bishkek City | C45: 1321.9 | D45: =C45*1000 | E45: =Construction_Clean!D45 | F45: =E45/D45*1000 | G45: Interpret cautiously because 2024 territorial reform changed relevant boundaries. | H45: https://www.stat.gov.kg/en/opendata/category/39/
A46: 2025 | B46: Osh City | C46: 473.5 | D46: =C46*1000 | E46: =Construction_Clean!D46 | F46: =E46/D46*1000 | G46: Interpret cautiously because 2024 territorial reform changed relevant boundaries. | H46: https://www.stat.gov.kg/en/opendata/category/39/

Sheet Validation_Log
A1: check | B1: expected | C1: observed | D1: status
A2: Number of territories per year | B2: 9 | C2: 9 in every year | D2: PASS
A3: Required years | B3: 2021, 2022, 2023, 2024, 2025 | C3: All present | D3: PASS
A4: Missing primary construction observations | B4: 0 | C4: 0 | D4: PASS
A5: Official unit | B5: Thousands of square meters | C5: thous. sq.m. | D5: PASS
A6: Primary observation count | B6: 45 | C6: 45 | D6: PASS
A7: Name standardization | B7: Nine stable manuscript labels | C7: Completed; source labels preserved separately | D7: PASS
A8: Administrative boundary comparability | B8: Investigated | C8: 2024 reform changed Bishkek and Osh related boundaries | D8: CAUTION
A9: Population normalization comparability | B9: Stable boundaries preferred | C9: Not fully stable across reform | D9: EXPLORATORY ONLY

Sheet Source_Log
A1: source_title | B1: organization | C1: exact_url | D1: format | E1: years | F1: geography | G1: unit_or_definition | H1: role_in_paper | I1: comparability_or_method_note
A2: Dwelling houses by territory | B2: National Statistical Committee of the Kyrgyz Republic | C2: https://stat.gov.kg/en/opendata/category/103/ | D2: Web table, Excel, XML SDMX, JSON | E2: 2021 to 2025 | F2: Nine territories | G2: Thousands of square meters | H2: Primary construction dataset for RQ1 to RQ4 | I2: Published series spans a 2024 administrative territorial reform; regional interpretation requires caution.
A3: Dwelling houses by territory JSON | B3: National Statistical Committee of the Kyrgyz Republic | C3: https://stat.gov.kg/en/opendata/category/103/json | D3: JSON | E3: 2021 to 2025 | F3: Nine territories | G3: Thousands of square meters | H3: Machine readable raw extraction used in this package | I3: Official endpoint accessed on 2026-10-02.
A4: Construction statistics and methodology | B4: National Statistical Committee of the Kyrgyz Republic | C4: https://stat.gov.kg/en/statistics/stroitelstvo/ | D4: Web page and methodology PDF | E4: Current methodology | F4: Kyrgyz Republic | G4: Commissioning of residential buildings and dormitories in square meters of total area, with territorial reporting | H4: Definitions, reporting forms, revision practices, methods | I4: Metadata describes preliminary data and revisions and includes reporting by legal and physical persons.
A5: Resident population as of the beginning of the year | B5: National Statistical Committee of the Kyrgyz Republic | C5: https://www.stat.gov.kg/en/opendata/category/39/ | D5: Web table, Excel, XML SDMX, JSON | E5: 2021 to 2025 | F5: Nine territories | G5: Thousands of people | H5: Optional population normalization | I5: 2024 administrative reform materially affects Bishkek, Chui, Osh City, and Osh Region comparability.
A6: Main results of investment and construction activities | B6: National Statistical Committee of the Kyrgyz Republic | C6: https://stat.gov.kg/en/publications/statisticheskij-byulleten-osnovnye-pokazateli-investicionnoj-i-stroitelnoj-deyatelnosti/ | D6: Annual statistical publication | E6: Annual editions | F6: Kyrgyz Republic and territories | G6: Construction and investment indicators | H6: Context and cross checking | I6: Use only variables matching the manuscript concept.
A7: 2022 Population and Housing Census | B7: National Statistical Committee of the Kyrgyz Republic | C7: https://www.stat.gov.kg/en/publications/perepis-naseleniya-i-zhilishnogo-fonda-kyrgyzskoj-respubliki-2022-goda-kniga-i-osnovnye-socialno-demograficheskie-harakteristiki/ | D7: Statistical publication | E7: 2022 | F7: Kyrgyz Republic and territories | G7: Population and housing characteristics | H7: Background context | I7: Not used as a substitute for annual population observations.
A8: Housing stock and housing conditions publication notice | B8: National Statistical Committee of the Kyrgyz Republic | C8: https://stat.gov.kg/ru/news/podgotovlena-k-pechati-statisticheskaya-publikaciya-zhilishnyj-fond-i-zhilishnye-usloviya-naseleniya-kyrgyzskoj-respubliki/ | D8: Official publication notice | E8: 2024 publication based largely on 2022 census | F8: Kyrgyz Republic | G8: Housing stock characteristics | H8: Supporting context | I8: Contextual source rather than analytical dataset.
A9: Enhanced services and infrastructure in cities of the Kyrgyz Republic | B9: World Bank | C9: https://www.worldbank.org/en/results/2023/08/30/enhanced-services-and-infrastructure-in-cities-of-the-kyrgyz-republic | D9: Institutional results article | E9: Published 2023 | F9: Kyrgyz Republic cities | G9: Urban services and municipal infrastructure context | H9: Introduction and discussion context | I9: Not a substitute for peer reviewed literature.

Sheet Literature_Matrix
A1: citation | B1: year | C1: journal | D1: doi | E1: url | F1: study_location | G1: study_period | H1: objective | I1: data_and_method | J1: main_findings_or_focus | K1: limitations_for_this_paper | L1: relevance | M1: section | N1: claims_supported
A2: Leupold, D. Skyrise, Smog and Seismic Menace. In the El Dorado of Bishkek's Elite Housing. | B2: 2023 | C2: Europe Asia Studies | D2: 10.1080/09668136.2023.2185203 | E2: https://www.tandfonline.com/doi/full/10.1080/09668136.2023.2185203 | F2: Bishkek | G2: Contemporary period, with housing boom discussed since 2012 | H2: Examine elite housing, new build development, and urban transformation | I2: Qualitative urban research | J2: Documents a recent Bishkek housing boom and associated social, environmental, and urban concerns | K2: Bishkek specific and not a national territorial comparison | L2: Recent housing development context | M2: Literature Review and Discussion | N2: Recent Bishkek apartment and elite housing development; urban transformation context
A3: Watson, C. S., Elliott, J. R., Amey, R. M. J., & Abdrakhmatov, K. E. Analyzing Satellite Derived 3D Building Inventories and Quantifying Urban Growth towards Active Faults. | B3: 2022 | C3: Remote Sensing | D3: 10.3390/rs14225790 | E3: https://www.mdpi.com/2072-4292/14/22/5790 | F3: Bishkek | G3: 1979 to 2021 | H3: Quantify urban building growth and expansion toward active faults | I3: Satellite imagery, deep learning building extraction, 3D building inventory | J3: Shows major long term physical urban expansion in Bishkek | K3: Measures built environment expansion, not the same as annual commissioned residential floor area | L3: Independent evidence of physical urban growth | M3: Literature Review and Discussion | N3: Long term Bishkek building growth and remote sensing measurement
A4: Omurakunova, G., Bao, A., Xu, W., et al. Expansion of Impervious Surfaces and Their Driving Forces in Highly Urbanized Cities in Kyrgyzstan. | B4: 2020 | C4: International Journal of Environmental Research and Public Health | D4: 10.3390/ijerph17010362 | E4: https://www.mdpi.com/1660-4601/17/1/362 | F4: Bishkek, Osh, Jalal Abad | G4: 1993 to 2017 | H4: Measure impervious surface expansion and examine associated drivers | I4: Remote sensing classification and comparative urban analysis | J4: Reports substantial impervious surface expansion, with different rates among the three cities | K4: Ends before the present study period and is limited to three cities | L4: Regional differences and physical expansion context | M4: Literature Review and Discussion | N4: Urban expansion differed among Bishkek, Osh, and Jalal Abad
A5: Hatcher, C., & Thieme, S. Institutional Transition: Internal Migration, the Propiska, and Post Socialist Urban Change in Bishkek, Kyrgyzstan. | B5: 2016 | C5: Urban Studies | D5: 10.1177/0042098015587252 | E5: https://journals.sagepub.com/doi/10.1177/0042098015587252 | F5: Bishkek | G5: Post Soviet period | H5: Examine internal migration, registration institutions, and urban change | I5: Qualitative institutional and migration analysis | J5: Shows how institutional transition and migration are negotiated in Bishkek's urban transformation | K5: Does not establish causal effects on the construction series | L5: Migration and institutional context | M5: Literature Review and Discussion | N5: Internal migration and propiska are important components of Bishkek's post Soviet urban change
A6: Hatcher, C. Globalising Homeownership: Housing Privatisation Schemes and the Private Rental Sector in Post Socialist Bishkek, Kyrgyzstan. | B6: 2015 | C6: International Development Planning Review | D6: 10.3828/idpr.2015.30 | E6: https://doi.org/10.3828/idpr.2015.30 | F6: Bishkek | G6: Post Soviet period | H6: Analyze housing privatization, homeownership, and rental sector transformation | I6: Housing institutions and qualitative policy analysis | J6: Describes privatization, property relations, rental rights, and housing system transformation | K6: Bishkek specific and institutional rather than quantitative regional construction analysis | L6: Housing system transformation | M6: Literature Review | N6: Post Soviet housing privatization and changing property relations in Bishkek
A7: Schröder, P. Urbanizing Bishkek: Interrelations of Boundaries, Migration, Group Size and Opportunity Structure. | B7: 2010 | C7: Central Asian Survey | D7: 10.1080/02634937.2010.537143 | E7: https://www.tandfonline.com/doi/full/10.1080/02634937.2010.537143 | F7: Bishkek | G7: Post Soviet period | H7: Examine urbanization and migration dynamics in Bishkek | I7: Urban and migration analysis | J7: Links migration, urban boundaries, and opportunity structures in Bishkek | K7: Older study and not focused on recent construction | L7: Demographic and urbanization context | M7: Literature Review | N7: Migration and urbanization shaped Bishkek's post Soviet development
A8: Flynn, M., Kosmarskaya, N., & Sabirova, G. The Place of Memory in Understanding Urban Change in Central Asia: The Cities of Bishkek and Ferghana. | B8: 2014 | C8: Europe Asia Studies | D8: 10.1080/09668136.2014.957926 | E8: https://www.tandfonline.com/doi/abs/10.1080/09668136.2014.957926 | F8: Bishkek and Ferghana | G8: Post Soviet period | H8: Use residents' memories to interpret urban change | I8: Qualitative interviews and urban change analysis | J8: Provides historical and experiential context for post Soviet urban transformation | K8: Not a construction measurement study | L8: Historical urban transformation context | M8: Literature Review | N8: Urban change in Bishkek should be situated within broader post Soviet transformation
A9: Kaganova, O., Akmatov, A., & Undeland, C. Introducing More Transparent and Efficient Land Management in Post Socialist Cities: Lessons from Kyrgyzstan. | B9: 2008 | C9: International Journal of Strategic Property Management | D9: 10.3846/1648-715X.2008.12.161-181 | E9: https://journals.vilniustech.lt/index.php/IJSPM/article/view/6763 | F9: Five Kyrgyz cities | G9: Reform period before 2008 | H9: Assess and improve municipal land management practices | I9: Applied institutional and municipal land management work | J9: Discusses municipal land inventory, registration, leasing, sales, and decentralization | K9: Older institutional study; publication page also shows a later online posting date | L9: Land management and development institutions | M9: Literature Review and Discussion | N9: Kyrgyz municipal land institutions changed substantially in the post Soviet period
A10: Bekhzanova, G. B., Dolonova, T. A., & Solpueva, A. K. State of Housing Construction in Kyrgyzstan. | B10: 2022 | C10: The Herald of KSUCTA | D10: 10.35803/1694-5298.2022.2.540-547 | E10: https://www.researchgate.net/publication/360465825_STATE_OF_HOUSING_CONSTRUCTION_IN_KYRGYZSTAN | F10: Kyrgyzstan | G10: Official statistics through about 2020 | H10: Assess the state of housing construction and housing needs | I10: Descriptive analysis of official housing statistics | J10: Discusses housing demand, supply conditions, and construction indicators | K10: Predates the 2021 to 2025 period and should be balanced with indexed literature | L10: Direct national housing construction context | M10: Literature Review | N10: Housing construction and housing need were already important national policy and sector issues before 2021
A11: Sykora, L., & Bouzarovski, S. Multiple Transformations: Conceptualising the Post Communist Urban Transition. | B11: 2012 | C11: Urban Studies | D11: 10.1177/0042098010397402 | E11: https://journals.sagepub.com/doi/10.1177/0042098010397402 | F11: Post communist cities | G11: Post 1989 transition | H11: Develop a conceptual framework for post communist urban transition | I11: Conceptual and comparative urban studies | J11: Frames institutional, social, and spatial transformations as interconnected processes | K11: Broad theoretical framework rather than Kyrgyzstan specific evidence | L11: Theoretical framework | M11: Literature Review and Discussion | N11: Post socialist urban change can be understood through interacting institutional, social, and spatial transformations
A12: Panzera, D., Cartone, A., & Postiglione, P. New Evidence on Measuring the Geographical Concentration of Economic Activities. | B12: 2022 | C12: Papers in Regional Science | D12: 10.1111/pirs.12644 | E12: https://onlinelibrary.wiley.com/doi/full/10.1111/pirs.12644 | F12: European NUTS 3 regions | G12: 2001 to 2018 | H12: Evaluate geographic concentration measures and spatial sensitivity | I12: Spatial concentration measures and decomposed locational Gini applications | J12: Shows that traditional concentration measures may miss spatial rearrangements because they ignore spatial interactions | K12: Economic activity is not identical to residential construction; methodological concepts only | L12: Supports concentration measure limitations | M12: Data and Methods and Limitations | N12: A nonspatial concentration measure does not account for distance or adjacency among territorial units
A13: Soltogulova, M. U., Derbisheva, E. D., & Asanov, R. K. Analysis of Housing Development in the Kyrgyz Republic. | B13: 2024 | C13: Bulletin of Science and Practice | D13: 10.33619/2414-2948/109/53 | E13: https://doi.org/10.33619/2414-2948/109/53 | F13: Kyrgyzstan | G13: Approximately 2019 to 2023 | H13: Analyze recent housing development and commissioning trends | I13: Descriptive analysis of housing commissioning, housing stock, prices, and sector factors | J13: Provides a recent five year national housing analysis | K13: Does not appear to provide the same nine territory 2021 to 2025 share and concentration design | L13: Important recent study for testing the research gap | M13: Literature Review and Research Gap | N13: Recent Kyrgyz scholarship already examines national housing commissioning trends, so novelty should be stated narrowly
A14: Toktalieva, K. A. Diagnostics of Construction of Residential Buildings in Urban and Rural Areas of the Kyrgyz Republic and Their Financing as a Platform for Development of the Construction Industry. | B14: 2025 | C14: News of Issyk Kul Forum of Central Asian Accountants and Auditors | D14: 10.63341/buhform.1.2025.122 | E14: https://doi.org/10.63341/buhform.1.2025.122 | F14: Kyrgyzstan | G14: Recent period | H14: Examine residential construction in urban and rural areas and financing | I14: Descriptive sector and financing analysis | J14: Addresses recent residential construction and financing in urban and rural categories | K14: Different geographic aggregation and research questions from the present nine territory concentration study | L14: Recent literature and gap testing | M14: Literature Review and Research Gap | N14: Recent research addresses urban and rural residential construction, requiring a narrow statement of this paper's contribution

Sheet Sensitivity_City_Region
A1: Each city combined with its surrounding region (Bishkek+Chui; Osh City+Osh Region). Values in thousand sq.m. unless stated. Generated by reproduce_analysis_v2.py.
A3: region | B3: 2021 | C3: 2025 | D3: pct_change | E3: share_2021_pct | F3: share_2025_pct
A4: Batken Region | B4: 63.4 | C4: 71.2 | D4: 12.3028 | E4: 4.8279 | F4: 3.9123
A5: Issyk Kul Region | B5: 85.8 | C5: 86.3 | D5: 0.5828 | E5: 6.5337 | F5: 4.742
A6: Jalal Abad Region | B6: 186.1 | C6: 311.8 | D6: 67.5443 | E6: 14.1715 | F6: 17.1328
A7: Naryn Region | B7: 43.1 | C7: 36.2 | D7: -16.0093 | E7: 3.2821 | F7: 1.9891
A8: Talas Region | B8: 63.2 | C8: 80.8 | D8: 27.8481 | E8: 4.8127 | F8: 4.4398
A9: Bishkek City + Chui Region | B9: 516.9 | C9: 832.8 | D9: 61.1143 | E9: 39.3619 | F9: 45.7608
A10: Osh City + Osh Region | B10: 354.7 | C10: 400.8 | D10: 12.9969 | E10: 27.0104 | F10: 22.0232

Sheet HHI_Comparison
A1: HHI for nine units, normalized HHI (H-1/N)/(1-1/N), and seven merged units.
A3: year | B3: hhi_9_units | C3: hhi_9_normalized | D3: hhi_7_merged | E3: hhi_7_normalized
A4: 2021 | B4: 0.157699 | C4: 0.052412 | D4: 0.257968 | E4: 0.134296
A5: 2022 | B5: 0.160999 | C5: 0.056123 | D5: 0.265107 | E5: 0.142625
A6: 2023 | B6: 0.184282 | C6: 0.082317 | D6: 0.288536 | E6: 0.169959
A7: 2024 | B7: 0.191906 | C7: 0.090894 | D7: 0.276983 | E7: 0.15648
A8: 2025 | B8: 0.188774 | C8: 0.087371 | D8: 0.293406 | E8: 0.175641

Sheet Robustness_TwoYearAvg
A1: Two-year averages (2021-22 vs 2024-25), thousand sq.m. Two-year HHI: 0.1591 -> 0.1898.
A3: region | B3: avg_2021_22 | C3: avg_2024_25 | D3: pct_change
A4: Batken Region | B4: 69.95 | C4: 70.05 | D4: 0.143
A5: Bishkek City | B5: 364.25 | C5: 578.05 | D5: 58.696
A6: Chui Region | B6: 194.8 | C6: 183.45 | D6: -5.826
A7: Issyk Kul Region | B7: 87.5 | C7: 84.6 | D7: -3.314
A8: Jalal Abad Region | B8: 198.7 | C8: 305.85 | D8: 53.926
A9: Naryn Region | B9: 41.6 | C9: 34.1 | D9: -18.029
A10: Osh City | B10: 107.7 | C10: 159.7 | D10: 48.282
A11: Osh Region | B11: 257.3 | C11: 198.6 | D11: -22.814
A12: Talas Region | B12: 66.1 | C12: 82.25 | D12: 24.433

Sheet Decomposition_Contribution
A1: Territory contribution to the 2021-2025 national change (last column), with growth and share measures.
A3: region | B3: y2021 | C3: y2025 | D3: abs_change | E3: pct_change | F3: cagr_pct | G3: share_2021_pct | H3: share_2025_pct | I3: share_change_pp | J3: contribution_to_national_change_pct
A4: Batken Region | B4: 63.4 | C4: 71.2 | D4: 7.8 | E4: 12.3028 | F4: 2.9432 | G4: 4.8279 | H4: 3.9123 | I4: -0.9156 | J4: 1.5394
A5: Bishkek City | B5: 348.6 | C5: 617 | D5: 268.4 | E5: 76.9937 | F5: 15.3425 | G5: 26.5458 | H5: 33.903 | I5: 7.3571 | J5: 52.9702
A6: Chui Region | B6: 168.3 | C6: 215.8 | D6: 47.5 | E6: 28.2234 | F6: 6.4123 | G6: 12.816 | H6: 11.8578 | I6: -0.9582 | J6: 9.3744
A7: Issyk Kul Region | B7: 85.8 | C7: 86.3 | D7: 0.5 | E7: 0.5828 | F7: 0.1454 | G7: 6.5337 | H7: 4.742 | I7: -1.7916 | J7: 0.0987
A8: Jalal Abad Region | B8: 186.1 | C8: 311.8 | D8: 125.7 | E8: 67.5443 | F8: 13.7712 | G8: 14.1715 | H8: 17.1328 | I8: 2.9613 | J8: 24.8076
A9: Naryn Region | B9: 43.1 | C9: 36.2 | D9: -6.9 | E9: -16.0093 | F9: -4.2678 | G9: 3.2821 | H9: 1.9891 | I9: -1.2929 | J9: -1.3618
A10: Osh City | B10: 116.8 | C10: 194.4 | D10: 77.6 | E10: 66.4384 | F10: 13.583 | G10: 8.8943 | H10: 10.6819 | I10: 1.7876 | J10: 15.3148
A11: Osh Region | B11: 237.9 | C11: 206.4 | D11: -31.5 | E11: -13.2409 | F11: -3.4886 | G11: 18.1161 | H11: 11.3413 | I11: -6.7748 | J11: -6.2167
A12: Talas Region | B12: 63.2 | C12: 80.8 | D12: 17.6 | E12: 27.8481 | F12: 6.3343 | G12: 4.8127 | H12: 4.4398 | I12: -0.3729 | J12: 3.4735

Sheet Population_A1
A1: Resident population at start of year, thousand persons (NSC). Boundary change in 2024.
A3: region | B3: 2021 | C3: 2022 | D3: 2023 | E3: 2024 | F3: 2025
A4: Batken Region | B4: 549 | C4: 559.5 | D4: 570.9 | E4: 583.4 | F4: 594.7
A5: Bishkek City | B5: 1088.3 | C5: 1113.8 | D5: 1145 | E5: 1294.8 | F5: 1321.9
A6: Chui Region | B6: 1038.7 | C6: 1054.5 | D6: 1068.7 | E6: 957.6 | F6: 971.3
A7: Issyk Kul Region | B7: 527.7 | C7: 533.8 | D7: 538.4 | E7: 544.4 | F7: 549.8
A8: Jalal Abad Region | B8: 1266.3 | C8: 1288.4 | D8: 1311 | E8: 1335.8 | F8: 1358.5
A9: Naryn Region | B9: 303.4 | C9: 306.5 | D9: 308.4 | E9: 312.1 | F9: 314.9
A10: Osh City | B10: 337.8 | C10: 350.6 | D10: 361.3 | E10: 463.1 | F10: 473.5
A11: Osh Region | B11: 1410.8 | C11: 1435.5 | D11: 1460.4 | E11: 1393.6 | F11: 1416.7
A12: Talas Region | B12: 267.6 | C12: 270.3 | D12: 273.5 | E12: 277.1 | F12: 280.5
